<?xml version="1.0" encoding="UTF-8"?>
<!-- Generated by org.testng.reporters.JUnitReportReporter -->
<testsuite hostname="LAPTOP-VKAG1RPA" failures="2" tests="18" name="com.extraPOSTest.testCases.inventory.maintenance.TC_Category" time="110.339" errors="0" timestamp="2021-02-05T11:30:33 IST" skipped="0">
  <testcase classname="com.extraPOSTest.testCases.inventory.maintenance.TC_Category" name="selectALL_forCategoryCode" time="6.505"/>
  <system-out/>
  <testcase classname="com.extraPOSTest.testCases.inventory.maintenance.TC_Category" name="createCategoryCode" time="4.628"/>
  <system-out/>
  <testcase classname="com.extraPOSTest.testCases.inventory.maintenance.TC_Category" name="createCategoryCode" time="10.078"/>
  <system-out/>
  <testcase classname="com.extraPOSTest.testCases.inventory.maintenance.TC_Category" name="createCategoryCode" time="5.394"/>
  <system-out/>
  <testcase classname="com.extraPOSTest.testCases.inventory.maintenance.TC_Category" name="createCategoryCode" time="7.087"/>
  <system-out/>
  <testcase classname="com.extraPOSTest.testCases.inventory.maintenance.TC_Category" name="createCategoryCode" time="3.644"/>
  <system-out/>
  <testcase classname="com.extraPOSTest.testCases.inventory.maintenance.TC_Category" name="saveCategoryCode" time="26.276">
    <failure message="No Error Message validation for save action expected [true] but found [false]" type="java.lang.AssertionError">
      <![CDATA[java.lang.AssertionError: No Error Message validation for save action expected [true] but found [false]
at org.testng.Assert.fail(Assert.java:99)
at org.testng.Assert.failNotEquals(Assert.java:1037)
at org.testng.Assert.assertTrue(Assert.java:45)
at com.extraPOSTest.testCases.inventory.maintenance.TC_Category.saveCategoryCode(TC_Category.java:347)
at java.base/jdk.internal.reflect.NativeMethodAccessorImpl.invoke0(Native Method)
at java.base/jdk.internal.reflect.NativeMethodAccessorImpl.invoke(NativeMethodAccessorImpl.java:64)
at java.base/jdk.internal.reflect.DelegatingMethodAccessorImpl.invoke(DelegatingMethodAccessorImpl.java:43)
at java.base/java.lang.reflect.Method.invoke(Method.java:564)
at org.testng.internal.MethodInvocationHelper.invokeMethod(MethodInvocationHelper.java:132)
at org.testng.internal.TestInvoker.invokeMethod(TestInvoker.java:599)
at org.testng.internal.TestInvoker.invokeTestMethod(TestInvoker.java:174)
at org.testng.internal.MethodRunner.runInSequence(MethodRunner.java:46)
at org.testng.internal.TestInvoker$MethodInvocationAgent.invoke(TestInvoker.java:822)
at org.testng.internal.TestInvoker.invokeTestMethods(TestInvoker.java:147)
at org.testng.internal.TestMethodWorker.invokeTestMethods(TestMethodWorker.java:146)
at org.testng.internal.TestMethodWorker.run(TestMethodWorker.java:128)
at java.base/java.util.ArrayList.forEach(ArrayList.java:1511)
at org.testng.TestRunner.privateRun(TestRunner.java:764)
at org.testng.TestRunner.run(TestRunner.java:585)
at org.testng.SuiteRunner.runTest(SuiteRunner.java:384)
at org.testng.SuiteRunner.runSequentially(SuiteRunner.java:378)
at org.testng.SuiteRunner.privateRun(SuiteRunner.java:337)
at org.testng.SuiteRunner.run(SuiteRunner.java:286)
at org.testng.SuiteRunnerWorker.runSuite(SuiteRunnerWorker.java:53)
at org.testng.SuiteRunnerWorker.run(SuiteRunnerWorker.java:96)
at org.testng.TestNG.runSuitesSequentially(TestNG.java:1218)
at org.testng.TestNG.runSuitesLocally(TestNG.java:1140)
at org.testng.TestNG.runSuites(TestNG.java:1069)
at org.testng.TestNG.run(TestNG.java:1037)
at org.testng.remote.AbstractRemoteTestNG.run(AbstractRemoteTestNG.java:115)
at org.testng.remote.RemoteTestNG.initAndRun(RemoteTestNG.java:251)
at org.testng.remote.RemoteTestNG.main(RemoteTestNG.java:77)
]]>
    </failure>
  </testcase> <!-- saveCategoryCode -->
  <system-out/>
  <testcase classname="com.extraPOSTest.testCases.inventory.maintenance.TC_Category" name="addTwoSameCategoryCode" time="0.677"/>
  <system-out/>
  <testcase classname="com.extraPOSTest.testCases.inventory.maintenance.TC_Category" name="addTwoSameCategoryCode" time="1.656"/>
  <system-out/>
  <testcase classname="com.extraPOSTest.testCases.inventory.maintenance.TC_Category" name="saveTwoCategoryCode" time="5.398"/>
  <system-out/>
  <testcase classname="com.extraPOSTest.testCases.inventory.maintenance.TC_Category" name="searchCategoryPage" time="3.344"/>
  <system-out/>
  <testcase classname="com.extraPOSTest.testCases.inventory.maintenance.TC_Category" name="searchCategoryPage" time="4.361"/>
  <system-out/>
  <testcase classname="com.extraPOSTest.testCases.inventory.maintenance.TC_Category" name="searchCategoryPage" time="3.414"/>
  <system-out/>
  <testcase classname="com.extraPOSTest.testCases.inventory.maintenance.TC_Category" name="searchCategoryPage" time="3.493"/>
  <system-out/>
  <testcase classname="com.extraPOSTest.testCases.inventory.maintenance.TC_Category" name="checkReverseOrderValidation_CategoryCode" time="21.667">
    <failure message="No validation for duplicate catcode expected [true] but found [false]" type="java.lang.AssertionError">
      <![CDATA[java.lang.AssertionError: No validation for duplicate catcode expected [true] but found [false]
at org.testng.Assert.fail(Assert.java:99)
at org.testng.Assert.failNotEquals(Assert.java:1037)
at org.testng.Assert.assertTrue(Assert.java:45)
at com.extraPOSTest.testCases.inventory.maintenance.TC_Category.checkReverseOrderValidation_CategoryCode(TC_Category.java:897)
at java.base/jdk.internal.reflect.NativeMethodAccessorImpl.invoke0(Native Method)
at java.base/jdk.internal.reflect.NativeMethodAccessorImpl.invoke(NativeMethodAccessorImpl.java:64)
at java.base/jdk.internal.reflect.DelegatingMethodAccessorImpl.invoke(DelegatingMethodAccessorImpl.java:43)
at java.base/java.lang.reflect.Method.invoke(Method.java:564)
at org.testng.internal.MethodInvocationHelper.invokeMethod(MethodInvocationHelper.java:132)
at org.testng.internal.TestInvoker.invokeMethod(TestInvoker.java:599)
at org.testng.internal.TestInvoker.invokeTestMethod(TestInvoker.java:174)
at org.testng.internal.MethodRunner.runInSequence(MethodRunner.java:46)
at org.testng.internal.TestInvoker$MethodInvocationAgent.invoke(TestInvoker.java:822)
at org.testng.internal.TestInvoker.invokeTestMethods(TestInvoker.java:147)
at org.testng.internal.TestMethodWorker.invokeTestMethods(TestMethodWorker.java:146)
at org.testng.internal.TestMethodWorker.run(TestMethodWorker.java:128)
at java.base/java.util.ArrayList.forEach(ArrayList.java:1511)
at org.testng.TestRunner.privateRun(TestRunner.java:764)
at org.testng.TestRunner.run(TestRunner.java:585)
at org.testng.SuiteRunner.runTest(SuiteRunner.java:384)
at org.testng.SuiteRunner.runSequentially(SuiteRunner.java:378)
at org.testng.SuiteRunner.privateRun(SuiteRunner.java:337)
at org.testng.SuiteRunner.run(SuiteRunner.java:286)
at org.testng.SuiteRunnerWorker.runSuite(SuiteRunnerWorker.java:53)
at org.testng.SuiteRunnerWorker.run(SuiteRunnerWorker.java:96)
at org.testng.TestNG.runSuitesSequentially(TestNG.java:1218)
at org.testng.TestNG.runSuitesLocally(TestNG.java:1140)
at org.testng.TestNG.runSuites(TestNG.java:1069)
at org.testng.TestNG.run(TestNG.java:1037)
at org.testng.remote.AbstractRemoteTestNG.run(AbstractRemoteTestNG.java:115)
at org.testng.remote.RemoteTestNG.initAndRun(RemoteTestNG.java:251)
at org.testng.remote.RemoteTestNG.main(RemoteTestNG.java:77)
]]>
    </failure>
  </testcase> <!-- checkReverseOrderValidation_CategoryCode -->
  <system-out/>
  <testcase classname="com.extraPOSTest.testCases.inventory.maintenance.TC_Category" name="checkReverseOrderValidation_CategoryCode" time="0.238"/>
  <system-out/>
  <testcase classname="com.extraPOSTest.testCases.inventory.maintenance.TC_Category" name="checkReverseOrderValidation_CategoryCode" time="1.897"/>
  <system-out/>
  <testcase classname="com.extraPOSTest.testCases.inventory.maintenance.TC_Category" name="checkReverseOrderValidation_CategoryCode" time="0.582"/>
  <system-out/>
</testsuite> <!-- com.extraPOSTest.testCases.inventory.maintenance.TC_Category -->
